running python3 main.py

getting error:

Traceback (most recent call last):
  File "main.py", line 245, in <module>
    main(opts)
  File "main.py", line 60, in main
    model = DGMG(
  File "/home/evalexii/Documents/IAAIP/housing-design/dgmg/model.py", line 337, in __init__
    self.conditioning_vector = ConditionVec("input.json").conditioning_vector
  File "/home/evalexii/Documents/IAAIP/housing-design/dgmg/model.py", line 61, in __init__
    exterior_walls_encoded = exterior_walls_encoder(exterior_walls_sequence)
  File "/home/evalexii/.local/lib/python3.8/site-packages/torch/nn/modules/module.py", line 1501, in _call_impl
    return forward_call(*args, **kwargs)
  File "/home/evalexii/Documents/IAAIP/housing-design/dgmg/model.py", line 17, in forward
    out, _ = self.lstm(x)
  File "/home/evalexii/.local/lib/python3.8/site-packages/torch/nn/modules/module.py", line 1501, in _call_impl
    return forward_call(*args, **kwargs)
  File "/home/evalexii/.local/lib/python3.8/site-packages/torch/nn/modules/rnn.py", line 812, in forward
    result = _VF.lstm(input, hx, self._flat_weights, self.bias, self.num_layers,
RuntimeError: mat1 and mat2 must have the same dtype

thinking:

might be something to do with the corners sequence, but idk because that is a separate encoder...
this was working before, so, just need to figure out what the deal is

recent work:

partially built graph initiated